Workbook
Name _Cd: 'Inputs Fijos'!$D$4
Name Cd: 'Inputs Fijos'!$D$5
Name CdA: 'Inputs Fijos'!$D$4
Name Crr: 'Inputs Fijos'!$D$7
Name eficiencia_drivetrain: 'Inputs Fijos'!$D$10
Name g: 'Inputs Fijos'!$D$9
Name m: 'Inputs Fijos'!$D$3
Name rho: 'Inputs Fijos'!$D$8

Sheet Inputs Fijos
B2: Parámetro | C2: Símbolo | D2: Valor | E2: Unidad
B3: Masa total | C3: m | D3: 453.592 | E3: kg
B4: CdA | C4: CdA | D4: =D5*D6 -> 0.3667 | E4: m²
B5: Cd | D5: 0.19
B6: Area Frontal | D6: 1.93 | E6: m^2
B7: Crr | C7: Crr | D7: 0.005 | E7: -
B8: Densidad aire | C8: ρ | D8: 1.225 | E8: kg/m³
B9: Gravedad | C9: g | D9: 9.81 | E9: m/s²
B10: Eficiencia drivetrain | C10: η | D10: 0.95 | E10: %
B11: Capacidad batería | C11: E_batt | D11: 5400 | E11: Wh
B12: Área panel | C12: A_panel | D12: 5.797 | E12: m²
B13: Eficiencia panel | C13: η_panel | D13: 0.255 | E13: %

Sheet Inputs Variables
C5: Cantidad de Vueltas
C6: Carga Inicial Bateria
C7: Carga Final Bateria
C8: SOC
C9: Potencia del Array

Sheet Track_Profile
F7: Total TIME | G7: =SUM(M13:M92)/60 -> 5.8280598 | H7: MIN
F8: Total Distance | G8: =F92 -> 3.03 | H8: miles
C12: Segment | D12: Type | E12: Distance (mi) | F12: Acummulated | G12: Grade (%) | H12: Expected Velocity (mph) | I12: Irradiance (W/m²) | K12: Distance (m) | L12: Velocity (m/s) | M12: Time (s) | N12: Drag Force | O12: Rolling Force | P12: Grade Force | Q12: Total Force(N) | R12: Motor Force | S12: Motor Power | T12: Energía consumida (Wh)
C13: 1 | D13: Recta | E13: 0.11 | F13: =E13 -> 0.11 | G13: 0 | H13: 25 | I13: 800 | K13: =1609.34*E13 -> 177.0274 | L13: =0.44704*H13 -> 11.176 | M13: =K13/L13 -> 15.839961 | N13: =0.5*rho*CdA*(L13^2) -> 28.053677 | O13: =Crr*m*g -> 22.248688 | P13: =m * g * G13 -> 0 | Q13: =SUM(N13:P13) -> 50.302364 | R13: =MAX(0,Q13) -> 50.302364 | S13: =R13*L13 -> 562.17922 | T13: =(S13*M13)/3600 -> 2.4735824
C14: 2 | E14: 0.01 | F14: =F13+E14 -> 0.12 | G14: 0.03 | H14: 26 | I14: 800 | K14: =1609.34*E14 -> 16.0934 | L14: =0.44704*H14 -> 11.62304 | M14: =K14/L14 -> 1.3846119 | N14: =0.5*rho*CdA*(L14^2) -> 30.342857 | O14: =Crr*m*g -> 22.248688 | P14: =m * g * G14 -> 133.49213 | Q14: =SUM(N14:P14) -> 186.08367 | R14: =MAX(0,Q14) -> 186.08367 | S14: =R14*L14 -> 2162.8579 | T14: =(S14*M14)/3600 -> 0.83186637
C15: 3 | E15: 0.01 | F15: =F14+E15 -> 0.13 | G15: 0.01 | H15: 27 | I15: 800 | K15: =1609.34*E15 -> 16.0934 | L15: =0.44704*H15 -> 12.07008 | M15: =K15/L15 -> 1.33333 | N15: =0.5*rho*CdA*(L15^2) -> 32.721809 | O15: =Crr*m*g -> 22.248688 | P15: =m * g * G15 -> 44.497375 | Q15: =SUM(N15:P15) -> 99.467871 | R15: =MAX(0,Q15) -> 99.467871 | S15: =R15*L15 -> 1200.5852 | T15: =(S15*M15)/3600 -> 0.44466007
C16: 4 | E16: 0.03 | F16: =F15+E16 -> 0.16 | G16: 0 | H16: 28 | I16: 800 | K16: =1609.34*E16 -> 48.2802 | L16: =0.44704*H16 -> 12.51712 | M16: =K16/L16 -> 3.8571333 | N16: =0.5*rho*CdA*(L16^2) -> 35.190532 | O16: =Crr*m*g -> 22.248688 | P16: =m * g * G16 -> 0 | Q16: =SUM(N16:P16) -> 57.43922 | R16: =MAX(0,Q16) -> 57.43922 | S16: =R16*L16 -> 718.97361 | T16: =(S16*M16)/3600 -> 0.77032695
C17: 5 | E17: 0.01 | F17: =F16+E17 -> 0.17 | G17: 0.01 | H17: 29 | I17: 800 | K17: =1609.34*E17 -> 16.0934 | L17: =0.44704*H17 -> 12.96416 | M17: =K17/L17 -> 1.2413762 | N17: =0.5*rho*CdA*(L17^2) -> 37.749027 | O17: =Crr*m*g -> 22.248688 | P17: =m * g * G17 -> 44.497375 | Q17: =SUM(N17:P17) -> 104.49509 | R17: =MAX(0,Q17) -> 104.49509 | S17: =R17*L17 -> 1354.6911 | T17: =(S17*M17)/3600 -> 0.46713369
C18: 6 | E18: 0.01 | F18: =F17+E18 -> 0.18 | G18: 0.02 | H18: 29 | I18: 800 | K18: =1609.34*E18 -> 16.0934 | L18: =0.44704*H18 -> 12.96416 | M18: =K18/L18 -> 1.2413762 | N18: =0.5*rho*CdA*(L18^2) -> 37.749027 | O18: =Crr*m*g -> 22.248688 | P18: =m * g * G18 -> 88.99475 | Q18: =SUM(N18:P18) -> 148.99247 | R18: =MAX(0,Q18) -> 148.99247 | S18: =R18*L18 -> 1931.5622 | T18: =(S18*M18)/3600 -> 0.66605426
C19: 7 | E19: 0.01 | F19: =F18+E19 -> 0.19 | G19: 0.04 | H19: 29 | I19: 800 | K19: =1609.34*E19 -> 16.0934 | L19: =0.44704*H19 -> 12.96416 | M19: =K19/L19 -> 1.2413762 | N19: =0.5*rho*CdA*(L19^2) -> 37.749027 | O19: =Crr*m*g -> 22.248688 | P19: =m * g * G19 -> 177.9895 | Q19: =SUM(N19:P19) -> 237.98722 | R19: =MAX(0,Q19) -> 237.98722 | S19: =R19*L19 -> 3085.3043 | T19: =(S19*M19)/3600 -> 1.0638954
C20: 8 | E20: 0.01 | F20: =F19+E20 -> 0.2 | G20: 0.02 | H20: 30 | I20: 800 | K20: =1609.34*E20 -> 16.0934 | L20: =0.44704*H20 -> 13.4112 | M20: =K20/L20 -> 1.199997 | N20: =0.5*rho*CdA*(L20^2) -> 40.397295 | O20: =Crr*m*g -> 22.248688 | P20: =m * g * G20 -> 88.99475 | Q20: =SUM(N20:P20) -> 151.64073 | R20: =MAX(0,Q20) -> 151.64073 | S20: =R20*L20 -> 2033.6842 | T20: =(S20*M20)/3600 -> 0.67789305
C21: 9 | E21: 0.01 | F21: =F20+E21 -> 0.21 | G21: 0 | H21: 31 | I21: 800 | K21: =1609.34*E21 -> 16.0934 | L21: =0.44704*H21 -> 13.85824 | M21: =K21/L21 -> 1.1612874 | N21: =0.5*rho*CdA*(L21^2) -> 43.135333 | O21: =Crr*m*g -> 22.248688 | P21: =m * g * G21 -> 0 | Q21: =SUM(N21:P21) -> 65.384021 | R21: =MAX(0,Q21) -> 65.384021 | S21: =R21*L21 -> 906.10746 | T21: =(S21*M21)/3600 -> 0.292292
C22: 10 | E22: 0.01 | F22: =F21+E22 -> 0.22 | G22: 0.01 | H22: 30 | I22: 800 | K22: =1609.34*E22 -> 16.0934 | L22: =0.44704*H22 -> 13.4112 | M22: =K22/L22 -> 1.199997 | N22: =0.5*rho*CdA*(L22^2) -> 40.397295 | O22: =Crr*m*g -> 22.248688 | P22: =m * g * G22 -> 44.497375 | Q22: =SUM(N22:P22) -> 107.14336 | R22: =MAX(0,Q22) -> 107.14336 | S22: =R22*L22 -> 1436.921 | T22: =(S22*M22)/3600 -> 0.47897247
C23: 11 | E23: 0.01 | F23: =F22+E23 -> 0.23 | G23: 0 | H23: 27 | I23: 800 | K23: =1609.34*E23 -> 16.0934 | L23: =0.44704*H23 -> 12.07008 | M23: =K23/L23 -> 1.33333 | N23: =0.5*rho*CdA*(L23^2) -> 32.721809 | O23: =Crr*m*g -> 22.248688 | P23: =m * g * G23 -> 0 | Q23: =SUM(N23:P23) -> 54.970496 | R23: =MAX(0,Q23) -> 54.970496 | S23: =R23*L23 -> 663.49829 | T23: =(S23*M23)/3600 -> 0.2457395
C24: 12 | D24: Curva #1 | E24: 0.02 | F24: =F23+E24 -> 0.25 | G24: 0.03 | H24: 26 | I24: 800 | K24: =1609.34*E24 -> 32.1868 | L24: =0.44704*H24 -> 11.62304 | M24: =K24/L24 -> 2.7692239 | N24: =0.5*rho*CdA*(L24^2) -> 30.342857 | O24: =Crr*m*g -> 22.248688 | P24: =m * g * G24 -> 133.49213 | Q24: =SUM(N24:P24) -> 186.08367 | R24: =MAX(0,Q24) -> 186.08367 | S24: =R24*L24 -> 2162.8579 | T24: =(S24*M24)/3600 -> 1.6637327
C25: 13 | E25: 0.01 | F25: =F24+E25 -> 0.26 | G25: -0.01 | H25: 30 | I25: 800 | K25: =1609.34*E25 -> 16.0934 | L25: =0.44704*H25 -> 13.4112 | M25: =K25/L25 -> 1.199997 | N25: =0.5*rho*CdA*(L25^2) -> 40.397295 | O25: =Crr*m*g -> 22.248688 | P25: =m * g * G25 -> -44.497375 | Q25: =SUM(N25:P25) -> 18.148607 | R25: =MAX(0,Q25) -> 18.148607 | S25: =R25*L25 -> 243.3946 | T25: =(S25*M25)/3600 -> 0.081131331
C26: 14 | E26: 0.01 | F26: =F25+E26 -> 0.27 | G26: -0.03 | H26: 32 | I26: 800 | K26: =1609.34*E26 -> 16.0934 | L26: =0.44704*H26 -> 14.30528 | M26: =K26/L26 -> 1.1249972 | N26: =0.5*rho*CdA*(L26^2) -> 45.963144 | O26: =Crr*m*g -> 22.248688 | P26: =m * g * G26 -> -133.49213 | Q26: =SUM(N26:P26) -> -65.280294 | R26: =MAX(0,Q26) -> 0 | S26: =R26*L26 -> 0 | T26: =(S26*M26)/3600 -> 0
C27: 15 | E27: 0.01 | F27: =F26+E27 -> 0.28 | G27: -0.01 | H27: 32 | I27: 800 | K27: =1609.34*E27 -> 16.0934 | L27: =0.44704*H27 -> 14.30528 | M27: =K27/L27 -> 1.1249972 | N27: =0.5*rho*CdA*(L27^2) -> 45.963144 | O27: =Crr*m*g -> 22.248688 | P27: =m * g * G27 -> -44.497375 | Q27: =SUM(N27:P27) -> 23.714456 | R27: =MAX(0,Q27) -> 23.714456 | S27: =R27*L27 -> 339.24194 | T27: =(S27*M27)/3600 -> 0.10601284
C28: 16 | E28: 0.02 | F28: =F27+E28 -> 0.3 | G28: 0 | H28: 34 | I28: 800 | K28: =1609.34*E28 -> 32.1868 | L28: =0.44704*H28 -> 15.19936 | M28: =K28/L28 -> 2.1176418 | N28: =0.5*rho*CdA*(L28^2) -> 51.888081 | O28: =Crr*m*g -> 22.248688 | P28: =m * g * G28 -> 0 | Q28: =SUM(N28:P28) -> 74.136768 | R28: =MAX(0,Q28) -> 74.136768 | S28: =R28*L28 -> 1126.8314 | T28: =(S28*M28)/3600 -> 0.66284037
C29: 17 | E29: =0.05 -> 0.05 | F29: =F28+E29 -> 0.35 | G29: -0.02 | H29: 36 | I29: 800 | K29: =1609.34*E29 -> 80.467 | L29: =0.44704*H29 -> 16.09344 | M29: =K29/L29 -> 4.9999876 | N29: =0.5*rho*CdA*(L29^2) -> 58.172104 | O29: =Crr*m*g -> 22.248688 | P29: =m * g * G29 -> -88.99475 | Q29: =SUM(N29:P29) -> -8.5739586 | R29: =MAX(0,Q29) -> 0 | S29: =R29*L29 -> 0 | T29: =(S29*M29)/3600 -> 0
C30: 18 | E30: 0.01 | F30: =F29+E30 -> 0.36 | G30: -0.01 | H30: 34 | I30: 800 | K30: =1609.34*E30 -> 16.0934 | L30: =0.44704*H30 -> 15.19936 | M30: =K30/L30 -> 1.0588209 | N30: =0.5*rho*CdA*(L30^2) -> 51.888081 | O30: =Crr*m*g -> 22.248688 | P30: =m * g * G30 -> -44.497375 | Q30: =SUM(N30:P30) -> 29.639393 | R30: =MAX(0,Q30) -> 29.639393 | S30: =R30*L30 -> 450.4998 | T30: =(S30*M30)/3600 -> 0.13249961
C31: 19 | E31: 0.08 | F31: =F30+E31 -> 0.44 | G31: 0 | H31: 38 | I31: 800 | K31: =1609.34*E31 -> 128.7472 | L31: =0.44704*H31 -> 16.98752 | M31: =K31/L31 -> 7.5789285 | N31: =0.5*rho*CdA*(L31^2) -> 64.815215 | O31: =Crr*m*g -> 22.248688 | P31: =m * g * G31 -> 0 | Q31: =SUM(N31:P31) -> 87.063902 | R31: =MAX(0,Q31) -> 87.063902 | S31: =R31*L31 -> 1478.9998 | T31: =(S31*M31)/3600 -> 3.113676
C32: 20 | D32: Recta | E32: 0.01 | F32: =F31+E32 -> 0.45 | G32: 0 | H32: 36 | I32: 800 | K32: =1609.34*E32 -> 16.0934 | L32: =0.44704*H32 -> 16.09344 | M32: =K32/L32 -> 0.99999751 | N32: =0.5*rho*CdA*(L32^2) -> 58.172104 | O32: =Crr*m*g -> 22.248688 | P32: =m * g * G32 -> 0 | Q32: =SUM(N32:P32) -> 80.420792 | R32: =MAX(0,Q32) -> 80.420792 | S32: =R32*L32 -> 1294.2472 | T32: =(S32*M32)/3600 -> 0.35951221
C33: 21 | E33: 0.01 | F33: =F32+E33 -> 0.46 | G33: 0.03 | H33: 32 | I33: 800 | K33: =1609.34*E33 -> 16.0934 | L33: =0.44704*H33 -> 14.30528 | M33: =K33/L33 -> 1.1249972 | N33: =0.5*rho*CdA*(L33^2) -> 45.963144 | O33: =Crr*m*g -> 22.248688 | P33: =m * g * G33 -> 133.49213 | Q33: =SUM(N33:P33) -> 201.70396 | R33: =MAX(0,Q33) -> 201.70396 | S33: =R33*L33 -> 2885.4316 | T33: =(S33*M33)/3600 -> 0.90169513
C34: 22 | E34: 0.01 | F34: =F33+E34 -> 0.47 | G34: 0.02 | H34: 32 | I34: 800 | K34: =1609.34*E34 -> 16.0934 | L34: =0.44704*H34 -> 14.30528 | M34: =K34/L34 -> 1.1249972 | N34: =0.5*rho*CdA*(L34^2) -> 45.963144 | O34: =Crr*m*g -> 22.248688 | P34: =m * g * G34 -> 88.99475 | Q34: =SUM(N34:P34) -> 157.20658 | R34: =MAX(0,Q34) -> 157.20658 | S34: =R34*L34 -> 2248.8842 | T34: =(S34*M34)/3600 -> 0.70277456
C35: 23 | E35: 0.01 | F35: =F34+E35 -> 0.48 | G35: 0 | H35: 34 | I35: 800 | K35: =1609.34*E35 -> 16.0934 | L35: =0.44704*H35 -> 15.19936 | M35: =K35/L35 -> 1.0588209 | N35: =0.5*rho*CdA*(L35^2) -> 51.888081 | O35: =Crr*m*g -> 22.248688 | P35: =m * g * G35 -> 0 | Q35: =SUM(N35:P35) -> 74.136768 | R35: =MAX(0,Q35) -> 74.136768 | S35: =R35*L35 -> 1126.8314 | T35: =(S35*M35)/3600 -> 0.33142018
C36: 24 | E36: 0.02 | F36: =F35+E36 -> 0.5 | G36: -0.02 | H36: 36 | I36: 800 | K36: =1609.34*E36 -> 32.1868 | L36: =0.44704*H36 -> 16.09344 | M36: =K36/L36 -> 1.999995 | N36: =0.5*rho*CdA*(L36^2) -> 58.172104 | O36: =Crr*m*g -> 22.248688 | P36: =m * g * G36 -> -88.99475 | Q36: =SUM(N36:P36) -> -8.5739586 | R36: =MAX(0,Q36) -> 0 | S36: =R36*L36 -> 0 | T36: =(S36*M36)/3600 -> 0
C37: 25 | E37: 0.14 | F37: =F36+E37 -> 0.64 | G37: 0 | H37: 38 | I37: 800 | K37: =1609.34*E37 -> 225.3076 | L37: =0.44704*H37 -> 16.98752 | M37: =K37/L37 -> 13.263125 | N37: =0.5*rho*CdA*(L37^2) -> 64.815215 | O37: =Crr*m*g -> 22.248688 | P37: =m * g * G37 -> 0 | Q37: =SUM(N37:P37) -> 87.063902 | R37: =MAX(0,Q37) -> 87.063902 | S37: =R37*L37 -> 1478.9998 | T37: =(S37*M37)/3600 -> 5.448933
C38: 26 | D38: Curva #2 | E38: 0.09 | F38: =F37+E38 -> 0.73 | G38: 0 | H38: 28 | I38: 800 | K38: =1609.34*E38 -> 144.8406 | L38: =0.44704*H38 -> 12.51712 | M38: =K38/L38 -> 11.5714 | N38: =0.5*rho*CdA*(L38^2) -> 35.190532 | O38: =Crr*m*g -> 22.248688 | P38: =m * g * G38 -> 0 | Q38: =SUM(N38:P38) -> 57.43922 | R38: =MAX(0,Q38) -> 57.43922 | S38: =R38*L38 -> 718.97361 | T38: =(S38*M38)/3600 -> 2.3109808
C39: 27 | D39: Recta | E39: 0.18 | F39: =F38+E39 -> 0.91 | G39: 0 | H39: 38 | I39: 800 | K39: =1609.34*E39 -> 289.6812 | L39: =0.44704*H39 -> 16.98752 | M39: =K39/L39 -> 17.052589 | N39: =0.5*rho*CdA*(L39^2) -> 64.815215 | O39: =Crr*m*g -> 22.248688 | P39: =m * g * G39 -> 0 | Q39: =SUM(N39:P39) -> 87.063902 | R39: =MAX(0,Q39) -> 87.063902 | S39: =R39*L39 -> 1478.9998 | T39: =(S39*M39)/3600 -> 7.005771
C40: 28 | D40: Curva #3 | E40: 0.1 | F40: =F39+E40 -> 1.01 | G40: 0 | H40: 28 | I40: 800 | K40: =1609.34*E40 -> 160.934 | L40: =0.44704*H40 -> 12.51712 | M40: =K40/L40 -> 12.857111 | N40: =0.5*rho*CdA*(L40^2) -> 35.190532 | O40: =Crr*m*g -> 22.248688 | P40: =m * g * G40 -> 0 | Q40: =SUM(N40:P40) -> 57.43922 | R40: =MAX(0,Q40) -> 57.43922 | S40: =R40*L40 -> 718.97361 | T40: =(S40*M40)/3600 -> 2.5677565
C41: 29 | D41: Curva #4 | E41: 0.09 | F41: =F40+E41 -> 1.1 | G41: 0 | H41: 28 | I41: 800 | K41: =1609.34*E41 -> 144.8406 | L41: =0.44704*H41 -> 12.51712 | M41: =K41/L41 -> 11.5714 | N41: =0.5*rho*CdA*(L41^2) -> 35.190532 | O41: =Crr*m*g -> 22.248688 | P41: =m * g * G41 -> 0 | Q41: =SUM(N41:P41) -> 57.43922 | R41: =MAX(0,Q41) -> 57.43922 | S41: =R41*L41 -> 718.97361 | T41: =(S41*M41)/3600 -> 2.3109808
C42: 30 | D42: Recta Pequeña | E42: 0.1 | F42: =F41+E42 -> 1.2 | G42: 0 | H42: 32 | I42: 800 | K42: =1609.34*E42 -> 160.934 | L42: =0.44704*H42 -> 14.30528 | M42: =K42/L42 -> 11.249972 | N42: =0.5*rho*CdA*(L42^2) -> 45.963144 | O42: =Crr*m*g -> 22.248688 | P42: =m * g * G42 -> 0 | Q42: =SUM(N42:P42) -> 68.211832 | R42: =MAX(0,Q42) -> 68.211832 | S42: =R42*L42 -> 975.78935 | T42: =(S42*M42)/3600 -> 3.0493341
C43: 31 | D43: Curva #5 | E43: 0.07 | F43: =F42+E43 -> 1.27 | G43: 0 | H43: 28 | I43: 800 | K43: =1609.34*E43 -> 112.6538 | L43: =0.44704*H43 -> 12.51712 | M43: =K43/L43 -> 8.9999776 | N43: =0.5*rho*CdA*(L43^2) -> 35.190532 | O43: =Crr*m*g -> 22.248688 | P43: =m * g * G43 -> 0 | Q43: =SUM(N43:P43) -> 57.43922 | R43: =MAX(0,Q43) -> 57.43922 | S43: =R43*L43 -> 718.97361 | T43: =(S43*M43)/3600 -> 1.7974295
C44: 32 | D44: Recta | E44: 0.14 | F44: =F43+E44 -> 1.41 | G44: 0 | H44: 38 | I44: 800 | K44: =1609.34*E44 -> 225.3076 | L44: =0.44704*H44 -> 16.98752 | M44: =K44/L44 -> 13.263125 | N44: =0.5*rho*CdA*(L44^2) -> 64.815215 | O44: =Crr*m*g -> 22.248688 | P44: =m * g * G44 -> 0 | Q44: =SUM(N44:P44) -> 87.063902 | R44: =MAX(0,Q44) -> 87.063902 | S44: =R44*L44 -> 1478.9998 | T44: =(S44*M44)/3600 -> 5.448933
C45: 33 | D45: Curva #6 | E45: 0.07 | F45: =F44+E45 -> 1.48 | G45: 0 | H45: 28 | I45: 800 | K45: =1609.34*E45 -> 112.6538 | L45: =0.44704*H45 -> 12.51712 | M45: =K45/L45 -> 8.9999776 | N45: =0.5*rho*CdA*(L45^2) -> 35.190532 | O45: =Crr*m*g -> 22.248688 | P45: =m * g * G45 -> 0 | Q45: =SUM(N45:P45) -> 57.43922 | R45: =MAX(0,Q45) -> 57.43922 | S45: =R45*L45 -> 718.97361 | T45: =(S45*M45)/3600 -> 1.7974295
C46: 34 | D46: Curva #7 | E46: 0.06 | F46: =F45+E46 -> 1.54 | G46: 0 | H46: 28 | I46: 800 | K46: =1609.34*E46 -> 96.5604 | L46: =0.44704*H46 -> 12.51712 | M46: =K46/L46 -> 7.7142665 | N46: =0.5*rho*CdA*(L46^2) -> 35.190532 | O46: =Crr*m*g -> 22.248688 | P46: =m * g * G46 -> 0 | Q46: =SUM(N46:P46) -> 57.43922 | R46: =MAX(0,Q46) -> 57.43922 | S46: =R46*L46 -> 718.97361 | T46: =(S46*M46)/3600 -> 1.5406539
C47: 35 | D47: Recta | E47: 0.07 | F47: =F46+E47 -> 1.61 | G47: 0 | H47: 36 | I47: 800 | K47: =1609.34*E47 -> 112.6538 | L47: =0.44704*H47 -> 16.09344 | M47: =K47/L47 -> 6.9999826 | N47: =0.5*rho*CdA*(L47^2) -> 58.172104 | O47: =Crr*m*g -> 22.248688 | P47: =m * g * G47 -> 0 | Q47: =SUM(N47:P47) -> 80.420792 | R47: =MAX(0,Q47) -> 80.420792 | S47: =R47*L47 -> 1294.2472 | T47: =(S47*M47)/3600 -> 2.5165855
C48: 36 | E48: 0.01 | F48: =F47+E48 -> 1.62 | G48: 0.01 | H48: 34 | I48: 800 | K48: =1609.34*E48 -> 16.0934 | L48: =0.44704*H48 -> 15.19936 | M48: =K48/L48 -> 1.0588209 | N48: =0.5*rho*CdA*(L48^2) -> 51.888081 | O48: =Crr*m*g -> 22.248688 | P48: =m * g * G48 -> 44.497375 | Q48: =SUM(N48:P48) -> 118.63414 | R48: =MAX(0,Q48) -> 118.63414 | S48: =R48*L48 -> 1803.1631 | T48: =(S48*M48)/3600 -> 0.53034076
C49: 37 | E49: 0.03 | F49: =F48+E49 -> 1.65 | G49: 0.02 | H49: 32 | I49: 800 | K49: =1609.34*E49 -> 48.2802 | L49: =0.44704*H49 -> 14.30528 | M49: =K49/L49 -> 3.3749916 | N49: =0.5*rho*CdA*(L49^2) -> 45.963144 | O49: =Crr*m*g -> 22.248688 | P49: =m * g * G49 -> 88.99475 | Q49: =SUM(N49:P49) -> 157.20658 | R49: =MAX(0,Q49) -> 157.20658 | S49: =R49*L49 -> 2248.8842 | T49: =(S49*M49)/3600 -> 2.1083237
...

Sheet Energy_Model
B5: Segment | C5: Drag Force | D5: Rolling Force | E5: Grade Force | F5: Total Force(N) | G5: Motor Force | H5: Motor Power | I5: Time (s) | J5: Energía consumida (Wh)
B6: =Track_Profile!C13 -> 1 | C6: =0.5*rho*CdA*(Track_Profile!H13^2) -> 140.37734 | D6: =Crr*m*g -> 22.248688 | E6: =m * g *Track_Profile!G13 -> 0 | F6: =SUM(C6:E6) -> 162.62603 | G6: =MAX(0,F6) -> 162.62603 | H6: =G6*Track_Profile!L13 -> 1817.5085 | I6: =Track_Profile!M13 -> 15.839961 | J6: =(H6*Track_Profile!M13)/3600 -> 7.9970176
B7: =Track_Profile!C14 -> 2 | C7: =0.5*rho*CdA*(Track_Profile!H14^2) -> 151.83213 | D7: =Crr*m*g -> 22.248688 | E7: =m * g *Track_Profile!G14 -> 133.49213 | F7: =SUM(C7:E7) -> 307.57295 | G7: =MAX(0,F7) -> 307.57295 | H7: =G7*Track_Profile!L14 -> 3574.9327 | I7: =Track_Profile!M14 -> 1.3846119 | J7: =(H7*Track_Profile!M14)/3600 -> 1.3749707 | M7: Energía Consumida por vuellta | P7: =SUM(J:J) -> 353.57489 | Q7: Wh
B8: =Track_Profile!C15 -> 3 | C8: =0.5*rho*CdA*(Track_Profile!H15^2) -> 163.73613 | D8: =Crr*m*g -> 22.248688 | E8: =m * g *Track_Profile!G15 -> 44.497375 | F8: =SUM(C8:E8) -> 230.4822 | G8: =MAX(0,F8) -> 230.4822 | H8: =G8*Track_Profile!L15 -> 2781.9386 | I8: =Track_Profile!M15 -> 1.33333 | J8: =(H8*Track_Profile!M15)/3600 -> 1.0303451 | P8: =5000/P7 -> 14.141276
B9: =Track_Profile!C16 -> 4 | C9: =0.5*rho*CdA*(Track_Profile!H16^2) -> 176.08934 | D9: =Crr*m*g -> 22.248688 | E9: =m * g *Track_Profile!G16 -> 0 | F9: =SUM(C9:E9) -> 198.33803 | G9: =MAX(0,F9) -> 198.33803 | H9: =G9*Track_Profile!L16 -> 2482.6209 | I9: =Track_Profile!M16 -> 3.8571333 | J9: =(H9*Track_Profile!M16)/3600 -> 2.6599443
B10: =Track_Profile!C17 -> 5 | C10: =0.5*rho*CdA*(Track_Profile!H17^2) -> 188.89175 | D10: =Crr*m*g -> 22.248688 | E10: =m * g *Track_Profile!G17 -> 44.497375 | F10: =SUM(C10:E10) -> 255.63782 | G10: =MAX(0,F10) -> 255.63782 | H10: =G10*Track_Profile!L17 -> 3314.1296 | I10: =Track_Profile!M17 -> 1.2413762 | J10: =(H10*Track_Profile!M17)/3600 -> 1.1428005
B11: =Track_Profile!C18 -> 6 | C11: =0.5*rho*CdA*(Track_Profile!H18^2) -> 188.89175 | D11: =Crr*m*g -> 22.248688 | E11: =m * g *Track_Profile!G18 -> 88.99475 | F11: =SUM(C11:E11) -> 300.13519 | G11: =MAX(0,F11) -> 300.13519 | H11: =G11*Track_Profile!L18 -> 3891.0006 | I11: =Track_Profile!M18 -> 1.2413762 | J11: =(H11*Track_Profile!M18)/3600 -> 1.341721
B12: =Track_Profile!C19 -> 7 | C12: =0.5*rho*CdA*(Track_Profile!H19^2) -> 188.89175 | D12: =Crr*m*g -> 22.248688 | E12: =m * g *Track_Profile!G19 -> 177.9895 | F12: =SUM(C12:E12) -> 389.12994 | G12: =MAX(0,F12) -> 389.12994 | H12: =G12*Track_Profile!L19 -> 5044.7428 | I12: =Track_Profile!M19 -> 1.2413762 | J12: =(H12*Track_Profile!M19)/3600 -> 1.7395622
B13: =Track_Profile!C20 -> 8 | C13: =0.5*rho*CdA*(Track_Profile!H20^2) -> 202.14337 | D13: =Crr*m*g -> 22.248688 | E13: =m * g *Track_Profile!G20 -> 88.99475 | F13: =SUM(C13:E13) -> 313.38681 | G13: =MAX(0,F13) -> 313.38681 | H13: =G13*Track_Profile!L20 -> 4202.8932 | I13: =Track_Profile!M20 -> 1.199997 | J13: =(H13*Track_Profile!M20)/3600 -> 1.4009609
B14: =Track_Profile!C21 -> 9 | C14: =0.5*rho*CdA*(Track_Profile!H21^2) -> 215.8442 | D14: =Crr*m*g -> 22.248688 | E14: =m * g *Track_Profile!G21 -> 0 | F14: =SUM(C14:E14) -> 238.09289 | G14: =MAX(0,F14) -> 238.09289 | H14: =G14*Track_Profile!L21 -> 3299.5484 | I14: =Track_Profile!M21 -> 1.1612874 | J14: =(H14*Track_Profile!M21)/3600 -> 1.0643678
B15: =Track_Profile!C22 -> 10 | C15: =0.5*rho*CdA*(Track_Profile!H22^2) -> 202.14337 | D15: =Crr*m*g -> 22.248688 | E15: =m * g *Track_Profile!G22 -> 44.497375 | F15: =SUM(C15:E15) -> 268.88944 | G15: =MAX(0,F15) -> 268.88944 | H15: =G15*Track_Profile!L22 -> 3606.13 | I15: =Track_Profile!M22 -> 1.199997 | J15: =(H15*Track_Profile!M22)/3600 -> 1.2020404
B16: =Track_Profile!C23 -> 11 | C16: =0.5*rho*CdA*(Track_Profile!H23^2) -> 163.73613 | D16: =Crr*m*g -> 22.248688 | E16: =m * g *Track_Profile!G23 -> 0 | F16: =SUM(C16:E16) -> 185.98482 | G16: =MAX(0,F16) -> 185.98482 | H16: =G16*Track_Profile!L23 -> 2244.8517 | I16: =Track_Profile!M23 -> 1.33333 | J16: =(H16*Track_Profile!M23)/3600 -> 0.83142448
B17: =Track_Profile!C24 -> 12 | C17: =0.5*rho*CdA*(Track_Profile!H24^2) -> 151.83213 | D17: =Crr*m*g -> 22.248688 | E17: =m * g *Track_Profile!G24 -> 133.49213 | F17: =SUM(C17:E17) -> 307.57295 | G17: =MAX(0,F17) -> 307.57295 | H17: =G17*Track_Profile!L24 -> 3574.9327 | I17: =Track_Profile!M24 -> 2.7692239 | J17: =(H17*Track_Profile!M24)/3600 -> 2.7499414
B18: =Track_Profile!C25 -> 13 | C18: =0.5*rho*CdA*(Track_Profile!H25^2) -> 202.14337 | D18: =Crr*m*g -> 22.248688 | E18: =m * g *Track_Profile!G25 -> -44.497375 | F18: =SUM(C18:E18) -> 179.89469 | G18: =MAX(0,F18) -> 179.89469 | H18: =G18*Track_Profile!L25 -> 2412.6036 | I18: =Track_Profile!M25 -> 1.199997 | J18: =(H18*Track_Profile!M25)/3600 -> 0.80419921
B19: =Track_Profile!C26 -> 14 | C19: =0.5*rho*CdA*(Track_Profile!H26^2) -> 229.99424 | D19: =Crr*m*g -> 22.248688 | E19: =m * g *Track_Profile!G26 -> -133.49213 | F19: =SUM(C19:E19) -> 118.7508 | G19: =MAX(0,F19) -> 118.7508 | H19: =G19*Track_Profile!L26 -> 1698.7635 | I19: =Track_Profile!M26 -> 1.1249972 | J19: =(H19*Track_Profile!M26)/3600 -> 0.53086227
B20: =Track_Profile!C27 -> 15 | C20: =0.5*rho*CdA*(Track_Profile!H27^2) -> 229.99424 | D20: =Crr*m*g -> 22.248688 | E20: =m * g *Track_Profile!G27 -> -44.497375 | F20: =SUM(C20:E20) -> 207.74555 | G20: =MAX(0,F20) -> 207.74555 | H20: =G20*Track_Profile!L27 -> 2971.8583 | I20: =Track_Profile!M27 -> 1.1249972 | J20: =(H20*Track_Profile!M27)/3600 -> 0.92870341
... B85: =Track_Profile!C92 -> 80 | C85: =0.5*rho*CdA*(Track_Profile!H92^2) -> 118.81538 | D85: =Crr*m*g -> 22.248688 | E85: =m * g *Track_Profile!G92 -> 0 | F85: =SUM(C85:E85) -> 141.06407 | G85: =MAX(0,F85) -> 141.06407 | H85: =G85*Track_Profile!L92 -> 1450.4095 | I85: =Track_Profile!M92 -> 15.652135 | J85: =(H85*Track_Profile!M92)/3600 -> 6.3061126

Sheet Sheet2

Sheet Solar_Model
C4: Segment | D4: Irradiance | E4: Solar Power | F4: Time | G4: Solar energy
C5: =Track_Profile!C13 -> 1 | D5: =Track_Profile!I13 -> 800 | E5: =D5*N6*N7 -> 1182.588 | F5: =Track_Profile!M13 -> 15.839961 | G5: =(E5*F5)/3600 -> 5.2033743
C6: =Track_Profile!C14 -> 2 | D6: =Track_Profile!I14 -> 800 | E6: =D6*$N$6*$N$7 -> 1182.588 | F6: =Track_Profile!M14 -> 1.3846119 | G6: =(E6*F6)/3600 -> 0.45484041 | L6: Área panel | M6: A_panel | N6: 5.797 | O6: m²
C7: =Track_Profile!C15 -> 3 | D7: =Track_Profile!I15 -> 800 | E7: =D7*$N$6*$N$7 -> 1182.588 | F7: =Track_Profile!M15 -> 1.33333 | G7: =(E7*F7)/3600 -> 0.43799447 | L7: Eficiencia panel | M7: η_panel | N7: 0.255 | O7: %
C8: =Track_Profile!C16 -> 4 | D8: =Track_Profile!I16 -> 800 | E8: =D8*$N$6*$N$7 -> 1182.588 | F8: =Track_Profile!M16 -> 3.8571333 | G8: =(E8*F8)/3600 -> 1.2670554
C9: =Track_Profile!C17 -> 5 | D9: =Track_Profile!I17 -> 800 | E9: =D9*$N$6*$N$7 -> 1182.588 | F9: =Track_Profile!M17 -> 1.2413762 | G9: =(E9*F9)/3600 -> 0.40778795
C10: =Track_Profile!C18 -> 6 | D10: =Track_Profile!I18 -> 800 | E10: =D10*$N$6*$N$7 -> 1182.588 | F10: =Track_Profile!M18 -> 1.2413762 | G10: =(E10*F10)/3600 -> 0.40778795
C11: =Track_Profile!C19 -> 7 | D11: =Track_Profile!I19 -> 800 | E11: =D11*$N$6*$N$7 -> 1182.588 | F11: =Track_Profile!M19 -> 1.2413762 | G11: =(E11*F11)/3600 -> 0.40778795
C12: =Track_Profile!C20 -> 8 | D12: =Track_Profile!I20 -> 800 | E12: =D12*$N$6*$N$7 -> 1182.588 | F12: =Track_Profile!M20 -> 1.199997 | G12: =(E12*F12)/3600 -> 0.39419502
C13: =Track_Profile!C21 -> 9 | D13: =Track_Profile!I21 -> 800 | E13: =D13*$N$6*$N$7 -> 1182.588 | F13: =Track_Profile!M21 -> 1.1612874 | G13: =(E13*F13)/3600 -> 0.38147905
C14: =Track_Profile!C22 -> 10 | D14: =Track_Profile!I22 -> 800 | E14: =D14*$N$6*$N$7 -> 1182.588 | F14: =Track_Profile!M22 -> 1.199997 | G14: =(E14*F14)/3600 -> 0.39419502
C15: =Track_Profile!C23 -> 11 | D15: =Track_Profile!I23 -> 800 | E15: =D15*$N$6*$N$7 -> 1182.588 | F15: =Track_Profile!M23 -> 1.33333 | G15: =(E15*F15)/3600 -> 0.43799447
C16: =Track_Profile!C24 -> 12 | D16: =Track_Profile!I24 -> 800 | E16: =D16*$N$6*$N$7 -> 1182.588 | F16: =Track_Profile!M24 -> 2.7692239 | G16: =(E16*F16)/3600 -> 0.90968082
C17: =Track_Profile!C25 -> 13 | D17: =Track_Profile!I25 -> 800 | E17: =D17*$N$6*$N$7 -> 1182.588 | F17: =Track_Profile!M25 -> 1.199997 | G17: =(E17*F17)/3600 -> 0.39419502
C18: =Track_Profile!C26 -> 14 | D18: =Track_Profile!I26 -> 800 | E18: =D18*$N$6*$N$7 -> 1182.588 | F18: =Track_Profile!M26 -> 1.1249972 | G18: =(E18*F18)/3600 -> 0.36955783
C19: =Track_Profile!C27 -> 15 | D19: =Track_Profile!I27 -> 800 | E19: =D19*$N$6*$N$7 -> 1182.588 | F19: =Track_Profile!M27 -> 1.1249972 | G19: =(E19*F19)/3600 -> 0.36955783
... C84: =Track_Profile!C92 -> 80 | D84: =Track_Profile!I92 -> 800 | E84: =D84*$N$6*$N$7 -> 1182.588 | F84: =Track_Profile!M92 -> 15.652135 | G84: =(E84*F84)/3600 -> 5.1416742

Sheet Energy_Balance
C5: Segment | D5: Motor Energy | E5: Solar Energy | F5: Delta Energy | G5: Battery Level | H5: Battery % | L5: Drainage from battery per lap | N5: =SUM(F6:F85) -> -238.70499 | O5: Wh
C6: =Track_Profile!C13 -> 1 | D6: =(Energy_Model!H6*Energy_Model!I6)/3600 -> 7.9970176 | E6: =Solar_Model!G5 -> 5.2033743 | F6: =E6-D6 -> -2.7936434 | G6: ='Inputs Fijos'!D11+F6 -> 5397.2064 | H6: =G6/5400 -> 0.99948266 | L6: Battery % After one lap | N6: =H85 -> 0.95579537
C7: =Track_Profile!C14 -> 2 | D7: =(Energy_Model!H7*Energy_Model!I7)/3600 -> 1.3749707 | E7: =Solar_Model!G6 -> 0.45484041 | F7: =E7-D7 -> -0.92013028 | G7: =G6+F7 -> 5396.2862 | H7: =G7/5400 -> 0.99931226
C8: =Track_Profile!C15 -> 3 | D8: =(Energy_Model!H8*Energy_Model!I8)/3600 -> 1.0303451 | E8: =Solar_Model!G7 -> 0.43799447 | F8: =E8-D8 -> -0.59235058 | G8: =G7+F8 -> 5395.6939 | H8: =G8/5400 -> 0.99920257
C9: =Track_Profile!C16 -> 4 | D9: =(Energy_Model!H9*Energy_Model!I9)/3600 -> 2.6599443 | E9: =Solar_Model!G8 -> 1.2670554 | F9: =E9-D9 -> -1.3928889 | G9: =G8+F9 -> 5394.301 | H9: =G9/5400 -> 0.99894463
C10: =Track_Profile!C17 -> 5 | D10: =(Energy_Model!H10*Energy_Model!I10)/3600 -> 1.1428005 | E10: =Solar_Model!G9 -> 0.40778795 | F10: =E10-D10 -> -0.7350125 | G10: =G9+F10 -> 5393.566 | H10: =G10/5400 -> 0.99880851
C11: =Track_Profile!C18 -> 6 | D11: =(Energy_Model!H11*Energy_Model!I11)/3600 -> 1.341721 | E11: =Solar_Model!G10 -> 0.40778795 | F11: =E11-D11 -> -0.93393307 | G11: =G10+F11 -> 5392.632 | H11: =G11/5400 -> 0.99863556
C12: =Track_Profile!C19 -> 7 | D12: =(Energy_Model!H12*Energy_Model!I12)/3600 -> 1.7395622 | E12: =Solar_Model!G11 -> 0.40778795 | F12: =E12-D12 -> -1.3317742 | G12: =G11+F12 -> 5391.3003 | H12: =G12/5400 -> 0.99838894
C13: =Track_Profile!C20 -> 8 | D13: =(Energy_Model!H13*Energy_Model!I13)/3600 -> 1.4009609 | E13: =Solar_Model!G12 -> 0.39419502 | F13: =E13-D13 -> -1.0067659 | G13: =G12+F13 -> 5390.2935 | H13: =G13/5400 -> 0.9982025
C14: =Track_Profile!C21 -> 9 | D14: =(Energy_Model!H14*Energy_Model!I14)/3600 -> 1.0643678 | E14: =Solar_Model!G13 -> 0.38147905 | F14: =E14-D14 -> -0.68288876 | G14: =G13+F14 -> 5389.6106 | H14: =G14/5400 -> 0.99807604
C15: =Track_Profile!C22 -> 10 | D15: =(Energy_Model!H15*Energy_Model!I15)/3600 -> 1.2020404 | E15: =Solar_Model!G14 -> 0.39419502 | F15: =E15-D15 -> -0.80784533 | G15: =G14+F15 -> 5388.8028 | H15: =G15/5400 -> 0.99792644
C16: =Track_Profile!C23 -> 11 | D16: =(Energy_Model!H16*Energy_Model!I16)/3600 -> 0.83142448 | E16: =Solar_Model!G15 -> 0.43799447 | F16: =E16-D16 -> -0.39343001 | G16: =G15+F16 -> 5388.4093 | H16: =G16/5400 -> 0.99785358
C17: =Track_Profile!C24 -> 12 | D17: =(Energy_Model!H17*Energy_Model!I17)/3600 -> 2.7499414 | E17: =Solar_Model!G16 -> 0.90968082 | F17: =E17-D17 -> -1.8402606 | G17: =G16+F17 -> 5386.5691 | H17: =G17/5400 -> 0.99751279
C18: =Track_Profile!C25 -> 13 | D18: =(Energy_Model!H18*Energy_Model!I18)/3600 -> 0.80419921 | E18: =Solar_Model!G17 -> 0.39419502 | F18: =E18-D18 -> -0.41000419 | G18: =G17+F18 -> 5386.1591 | H18: =G18/5400 -> 0.99743687
... C85: =Track_Profile!C92 -> 80 | D85: =(Energy_Model!H85*Energy_Model!I85)/3600 -> 6.3061126 | E85: =Solar_Model!G84 -> 5.1416742 | F85: =E85-D85 -> -1.1644384 | G85: =G84+F85 -> 5161.295 | H85: =G85/5400 -> 0.95579537

Sheet Dashboard
BA3: Battery vs Distance
AV4: =BL4 -> Expected Velocity (mph) | AX4: =BJ4 -> Motor Power | BA4: =Energy_Balance!G5 -> Battery Level | BB4: =Track_Profile!F12 -> Acummulated | BE4: =Solar_Model!E4 -> Solar Power | BG4: =Energy_Balance!F5 -> Delta Energy | BH4: =Track_Profile!F12 -> Acummulated | BJ4: =Energy_Model!H5 -> Motor Power | BK4: =BH4 -> Acummulated | BL4: =Track_Profile!H12 -> Expected Velocity (mph)
AV5: =BL5 -> 25 | AX5: =BJ5 -> 1817.5085 | BA5: =Energy_Balance!G6 -> 5397.2064 | BB5: =Track_Profile!F13 -> 0.11 | BE5: =Solar_Model!E5 -> 1182.588 | BG5: =Energy_Balance!F6 -> -2.7936434 | BH5: =Track_Profile!F13 -> 0.11 | BJ5: =Energy_Model!H6 -> 1817.5085 | BK5: =BH5 -> 0.11 | BL5: =Track_Profile!H13 -> 25
AV6: =BL6 -> 26 | AX6: =BJ6 -> 3574.9327 | BA6: =Energy_Balance!G7 -> 5396.2862 | BB6: =Track_Profile!F14 -> 0.12 | BE6: =Solar_Model!E6 -> 1182.588 | BG6: =Energy_Balance!F7 -> -0.92013028 | BH6: =Track_Profile!F14 -> 0.12 | BJ6: =Energy_Model!H7 -> 3574.9327 | BK6: =BH6 -> 0.12 | BL6: =Track_Profile!H14 -> 26
AV7: =BL7 -> 27 | AX7: =BJ7 -> 2781.9386 | BA7: =Energy_Balance!G8 -> 5395.6939 | BB7: =Track_Profile!F15 -> 0.13 | BE7: =Solar_Model!E7 -> 1182.588 | BG7: =Energy_Balance!F8 -> -0.59235058 | BH7: =Track_Profile!F15 -> 0.13 | BJ7: =Energy_Model!H8 -> 2781.9386 | BK7: =BH7 -> 0.13 | BL7: =Track_Profile!H15 -> 27
AV8: =BL8 -> 28 | AX8: =BJ8 -> 2482.6209 | BA8: =Energy_Balance!G9 -> 5394.301 | BB8: =Track_Profile!F16 -> 0.16 | BE8: =Solar_Model!E8 -> 1182.588 | BG8: =Energy_Balance!F9 -> -1.3928889 | BH8: =Track_Profile!F16 -> 0.16 | BJ8: =Energy_Model!H9 -> 2482.6209 | BK8: =BH8 -> 0.16 | BL8: =Track_Profile!H16 -> 28
AV9: =BL9 -> 29 | AX9: =BJ9 -> 3314.1296 | BA9: =Energy_Balance!G10 -> 5393.566 | BB9: =Track_Profile!F17 -> 0.17 | BE9: =Solar_Model!E9 -> 1182.588 | BG9: =Energy_Balance!F10 -> -0.7350125 | BH9: =Track_Profile!F17 -> 0.17 | BJ9: =Energy_Model!H10 -> 3314.1296 | BK9: =BH9 -> 0.17 | BL9: =Track_Profile!H17 -> 29
AV10: =BL10 -> 29 | AX10: =BJ10 -> 3891.0006 | BA10: =Energy_Balance!G11 -> 5392.632 | BB10: =Track_Profile!F18 -> 0.18 | BE10: =Solar_Model!E10 -> 1182.588 | BG10: =Energy_Balance!F11 -> -0.93393307 | BH10: =Track_Profile!F18 -> 0.18 | BJ10: =Energy_Model!H11 -> 3891.0006 | BK10: =BH10 -> 0.18 | BL10: =Track_Profile!H18 -> 29
AV11: =BL11 -> 29 | AX11: =BJ11 -> 5044.7428 | BA11: =Energy_Balance!G12 -> 5391.3003 | BB11: =Track_Profile!F19 -> 0.19 | BE11: =Solar_Model!E11 -> 1182.588 | BG11: =Energy_Balance!F12 -> -1.3317742 | BH11: =Track_Profile!F19 -> 0.19 | BJ11: =Energy_Model!H12 -> 5044.7428 | BK11: =BH11 -> 0.19 | BL11: =Track_Profile!H19 -> 29
AV12: =BL12 -> 30 | AX12: =BJ12 -> 4202.8932 | BA12: =Energy_Balance!G13 -> 5390.2935 | BB12: =Track_Profile!F20 -> 0.2 | BE12: =Solar_Model!E12 -> 1182.588 | BG12: =Energy_Balance!F13 -> -1.0067659 | BH12: =Track_Profile!F20 -> 0.2 | BJ12: =Energy_Model!H13 -> 4202.8932 | BK12: =BH12 -> 0.2 | BL12: =Track_Profile!H20 -> 30
AV13: =BL13 -> 31 | AX13: =BJ13 -> 3299.5484 | BA13: =Energy_Balance!G14 -> 5389.6106 | BB13: =Track_Profile!F21 -> 0.21 | BE13: =Solar_Model!E13 -> 1182.588 | BG13: =Energy_Balance!F14 -> -0.68288876 | BH13: =Track_Profile!F21 -> 0.21 | BJ13: =Energy_Model!H14 -> 3299.5484 | BK13: =BH13 -> 0.21 | BL13: =Track_Profile!H21 -> 31
AV14: =BL14 -> 30 | AX14: =BJ14 -> 3606.13 | BA14: =Energy_Balance!G15 -> 5388.8028 | BB14: =Track_Profile!F22 -> 0.22 | BE14: =Solar_Model!E14 -> 1182.588 | BG14: =Energy_Balance!F15 -> -0.80784533 | BH14: =Track_Profile!F22 -> 0.22 | BJ14: =Energy_Model!H15 -> 3606.13 | BK14: =BH14 -> 0.22 | BL14: =Track_Profile!H22 -> 30
AV15: =BL15 -> 27 | AX15: =BJ15 -> 2244.8517 | BA15: =Energy_Balance!G16 -> 5388.4093 | BB15: =Track_Profile!F23 -> 0.23 | BE15: =Solar_Model!E15 -> 1182.588 | BG15: =Energy_Balance!F16 -> -0.39343001 | BH15: =Track_Profile!F23 -> 0.23 | BJ15: =Energy_Model!H16 -> 2244.8517 | BK15: =BH15 -> 0.23 | BL15: =Track_Profile!H23 -> 27
... AV84: =BL84 -> 23 | AX84: =BJ84 -> 1450.4095 | BA84: =Energy_Balance!G85 -> 5161.295 | BB84: =Track_Profile!F92 -> 3.03 | BE84: =Solar_Model!E84 -> 1182.588 | BG84: =Energy_Balance!F85 -> -1.1644384 | BH84: =Track_Profile!F92 -> 3.03 | BJ84: =Energy_Model!H85 -> 1450.4095 | BK84: =BH84 -> 3.03 | BL84: =Track_Profile!H92 -> 23
